[MFLOG|0|2025-04-17T09:19:14.831916Z|runtime|d5ee9b94-9884-4e7f-a556-e19382203bf6]<flow EntrenamientoFlow step entrenar> failed:
[MFLOG|0|2025-04-17T09:19:14.842174Z|runtime|bb794c34-c17f-4d5c-af55-7b3f6e464109]    Internal error
[MFLOG|0|2025-04-17T09:19:14.844211Z|runtime|7e3d6afb-296e-4318-afea-d4ef09062c8e]Traceback (most recent call last):
[MFLOG|0|2025-04-17T09:19:14.844449Z|runtime|d3ddd71f-27b3-4123-b422-544ee58a43af]  File "/home/clau/proyectos/metaflow/Practica-SIE-METAFLOW/venv/lib/python3.12/site-packages/metaflow/cli.py", line 611, in main
[MFLOG|0|2025-04-17T09:19:14.844693Z|runtime|d9d5ee6e-11e4-4eee-ba28-4fe3e05e800a]    start(auto_envvar_prefix="METAFLOW", obj=state)
[MFLOG|0|2025-04-17T09:19:14.844819Z|runtime|419080d1-7b8d-46bc-b712-985b495e36d5]  File "/home/clau/proyectos/metaflow/Practica-SIE-METAFLOW/venv/lib/python3.12/site-packages/metaflow/_vendor/click/core.py", line 829, in __call__
[MFLOG|0|2025-04-17T09:19:14.844993Z|runtime|751dca8a-7862-4244-8baa-4932c9e6890b]    return self.main(args, kwargs)
[MFLOG|0|2025-04-17T09:19:14.845152Z|runtime|e845bee9-8436-424c-884e-0f6d362d933b]           ^^^^^^^^^^^^^^^^^^^^^^^^^^
[MFLOG|0|2025-04-17T09:19:14.845515Z|runtime|13c2c43c-5356-486c-a13d-eabdef9f90fa]  File "/home/clau/proyectos/metaflow/Practica-SIE-METAFLOW/venv/lib/python3.12/site-packages/metaflow/_vendor/click/core.py", line 782, in main
[MFLOG|0|2025-04-17T09:19:14.845912Z|runtime|d5ce8073-1e91-441f-a826-3328a484aa01]    rv = self.invoke(ctx)
[MFLOG|0|2025-04-17T09:19:14.846153Z|runtime|2de9c2f6-e91d-47ec-9a6e-20b53b696b03]         ^^^^^^^^^^^^^^^^
[MFLOG|0|2025-04-17T09:19:14.846363Z|runtime|01e79b47-131b-4f3a-b44d-e941f3c62e93]  File "/home/clau/proyectos/metaflow/Practica-SIE-METAFLOW/venv/lib/python3.12/site-packages/metaflow/cli_components/utils.py", line 69, in invoke
[MFLOG|0|2025-04-17T09:19:14.846570Z|runtime|2828d992-c469-4b4b-ba68-0bc603731fc7]    return _process_result(sub_ctx.command.invoke(sub_ctx))
[MFLOG|0|2025-04-17T09:19:14.846770Z|runtime|1f9d0568-08ee-4dfd-a617-274a7905b165]                           ^^^^^^^^^^^^^^^^^^^^^^^^^^^^^^^
[MFLOG|0|2025-04-17T09:19:14.846963Z|runtime|bf5d43d9-40f9-47db-9e6b-1d4eec69087a]  File "/home/clau/proyectos/metaflow/Practica-SIE-METAFLOW/venv/lib/python3.12/site-packages/metaflow/_vendor/click/core.py", line 1066, in invoke
[MFLOG|0|2025-04-17T09:19:14.847162Z|runtime|7e19ea9e-aa40-4d3b-9d80-f0dcdb06af59]    return ctx.invoke(self.callback, ctx.params)
[MFLOG|0|2025-04-17T09:19:14.847371Z|runtime|47380924-86fe-45ab-abd9-9f8359abe7fe]           ^^^^^^^^^^^^^^^^^^^^^^^^^^^^^^^^^^^^^^^
[MFLOG|0|2025-04-17T09:19:14.847570Z|runtime|b4045755-6f8d-4410-bfaf-a8638c4393f2]  File "/home/clau/proyectos/metaflow/Practica-SIE-METAFLOW/venv/lib/python3.12/site-packages/metaflow/_vendor/click/core.py", line 610, in invoke
[MFLOG|0|2025-04-17T09:19:14.847839Z|runtime|ac1b62da-1af1-44d0-85c2-b0de030c8592]    return callback(args, kwargs)
[MFLOG|0|2025-04-17T09:19:15.041951Z|runtime|e2edddcb-b5d4-4880-8bc9-7a507eef8bfe]           ^^^^^^^^^^^^^^^^^^^^^^^^^
[MFLOG|0|2025-04-17T09:19:15.042113Z|runtime|12bd0c84-7c65-4a03-91c2-3bfc25fdc451]  File "/home/clau/proyectos/metaflow/Practica-SIE-METAFLOW/venv/lib/python3.12/site-packages/metaflow/tracing/__init__.py", line 27, in wrapper_func
[MFLOG|0|2025-04-17T09:19:15.042242Z|runtime|7d1583c6-325d-4675-8c14-33c3c01154a2]    return func(args, kwargs)
[MFLOG|0|2025-04-17T09:19:15.042391Z|runtime|528d5ec7-dda1-4b89-a735-6e11e30e56bd]           ^^^^^^^^^^^^^^^^^^^^^
[MFLOG|0|2025-04-17T09:19:15.042610Z|runtime|056971bf-3aff-4dca-bbb6-5da2ff462b9f]  File "/home/clau/proyectos/metaflow/Practica-SIE-METAFLOW/venv/lib/python3.12/site-packages/metaflow/_vendor/click/decorators.py", line 21, in new_func
[MFLOG|0|2025-04-17T09:19:15.043031Z|runtime|1107b4ec-1453-4a23-81d6-defd1b66d843]    return f(get_current_context(), args, kwargs)
[MFLOG|0|2025-04-17T09:19:15.043470Z|runtime|0a59b07f-8bbc-4d51-9933-7b0deb4379d3]           ^^^^^^^^^^^^^^^^^^^^^^^^^^^^^^^^^^^^^^^^^
[MFLOG|0|2025-04-17T09:19:15.043685Z|runtime|2e370b36-234b-48cb-bad0-1470fe1d15df]  File "/home/clau/proyectos/metaflow/Practica-SIE-METAFLOW/venv/lib/python3.12/site-packages/metaflow/cli_components/step_cmd.py", line 167, in step
[MFLOG|0|2025-04-17T09:19:15.043866Z|runtime|93108013-8c10-469a-8039-ae3b3c87e762]    task.run_step(
[MFLOG|0|2025-04-17T09:19:15.044051Z|runtime|f506dd38-4ec7-4a2c-8750-1f4aafdca3f9]  File "/home/clau/proyectos/metaflow/Practica-SIE-METAFLOW/venv/lib/python3.12/site-packages/metaflow/task.py", line 672, in run_step
[MFLOG|0|2025-04-17T09:19:15.044236Z|runtime|2a95012f-6be0-4815-8cb5-0c4a13beebd9]    self._exec_step_function(step_func)
[MFLOG|0|2025-04-17T09:19:15.044371Z|runtime|fe19c7c4-806c-44c0-b54f-69ce6c5e5d52]  File "/home/clau/proyectos/metaflow/Practica-SIE-METAFLOW/venv/lib/python3.12/site-packages/metaflow/task.py", line 62, in _exec_step_function
[MFLOG|0|2025-04-17T09:19:15.044457Z|runtime|e528f9f5-e87a-46f7-91d6-10bab17056da]    step_function()
[MFLOG|0|2025-04-17T09:19:15.044575Z|runtime|42fe903e-9430-4afb-afc3-f02d594f9519]  File "/home/clau/proyectos/metaflow/Practica-SIE-METAFLOW/FLOWS/entrenamiento.py", line 22, in entrenar
[MFLOG|0|2025-04-17T09:19:15.044762Z|runtime|3c8c5a65-bb4d-40b4-be20-3583a4e58b0a]    X_train = self.train[features]
[MFLOG|0|2025-04-17T09:19:15.044927Z|runtime|cf4547d2-7f70-4ec8-9b9c-bbc0bdb53012]              ~~~~~~~~~~^^^^^^^^^^
[MFLOG|0|2025-04-17T09:19:15.045060Z|runtime|be8a6a9b-a393-4635-b036-183796cff101]  File "/home/clau/proyectos/metaflow/Practica-SIE-METAFLOW/venv/lib/python3.12/site-packages/pandas/core/frame.py", line 4108, in __getitem__
[MFLOG|0|2025-04-17T09:19:15.045181Z|runtime|b3eb9646-639f-4ba8-9120-90e6cb397c31]    indexer = self.columns._get_indexer_strict(key, "columns")[1]
[MFLOG|0|2025-04-17T09:19:15.045382Z|runtime|7d2c9e1c-e7c3-4c05-b6db-ebe91051150e]              ^^^^^^^^^^^^^^^^^^^^^^^^^^^^^^^^^^^^^^^^^^^^^^^^
[MFLOG|0|2025-04-17T09:19:15.045648Z|runtime|ff77b910-4376-4a32-aa0e-8665f2eb6b4d]  File "/home/clau/proyectos/metaflow/Practica-SIE-METAFLOW/venv/lib/python3.12/site-packages/pandas/core/indexes/base.py", line 6200, in _get_indexer_strict
[MFLOG|0|2025-04-17T09:19:15.045756Z|runtime|4137dd92-5915-4870-b539-40f047dafb47]    self._raise_if_missing(keyarr, indexer, axis_name)
[MFLOG|0|2025-04-17T09:19:15.045857Z|runtime|0ab204ba-57d3-4825-a995-54ef15e7eaca]  File "/home/clau/proyectos/metaflow/Practica-SIE-METAFLOW/venv/lib/python3.12/site-packages/pandas/core/indexes/base.py", line 6252, in _raise_if_missing
[MFLOG|0|2025-04-17T09:19:15.046022Z|runtime|d6e7fa02-beec-4908-80e2-45eb59304f0f]    raise KeyError(f"{not_found} not in index")
[MFLOG|0|2025-04-17T09:19:15.046106Z|runtime|18c3fc2c-f81a-4f2f-a8ac-f7749347e45d]KeyError: "['gf_ult5', 'ga_ult5'] not in index"
[MFLOG|0|2025-04-17T09:19:15.046229Z|runtime|dfa9f175-73f2-485f-8e46-0825d0d570b4]
[MFLOG|0|2025-04-17T09:19:15.046727Z|runtime|99e454ba-5cf2-4588-a922-f9010667406d]Task failed.